<?xml version="1.0" encoding="UTF-8"?>
<!-- Generated by org.testng.reporters.JUnitReportReporter -->
<testsuite skipped="5" hostname="RAM-PC" name="com.qa.retryFailedTCUsingListener.TestCase" tests="7" failures="2" timestamp="16 Dec 2019 07:48:46 GMT" time="0.071" errors="0">
  <testcase name="Test1" time="0.052" classname="com.qa.retryFailedTCUsingListener.TestCase">
    <skipped/>
  </testcase> <!-- Test1 -->
  <testcase name="Test1" time="0.003" classname="com.qa.retryFailedTCUsingListener.TestCase">
    <skipped/>
  </testcase> <!-- Test1 -->
  <testcase name="Test2" time="0.003" classname="com.qa.retryFailedTCUsingListener.TestCase">
    <failure type="java.lang.AssertionError" message="expected [true] but found [false]">
      <![CDATA[java.lang.AssertionError: expected [true] but found [false]
at org.testng.Assert.fail(Assert.java:96)
at org.testng.Assert.failNotEquals(Assert.java:776)
at org.testng.Assert.assertEqualsImpl(Assert.java:137)
at org.testng.Assert.assertEquals(Assert.java:118)
at org.testng.Assert.assertEquals(Assert.java:568)
at org.testng.Assert.assertEquals(Assert.java:578)
at com.qa.retryFailedTCUsingListener.TestCase.Test2(TestCase.java:17)
at sun.reflect.NativeMethodAccessorImpl.invoke0(Native Method)
at sun.reflect.NativeMethodAccessorImpl.invoke(Unknown Source)
at sun.reflect.DelegatingMethodAccessorImpl.invoke(Unknown Source)
at java.lang.reflect.Method.invoke(Unknown Source)
at org.testng.internal.MethodInvocationHelper.invokeMethod(MethodInvocationHelper.java:124)
at org.testng.internal.Invoker.invokeMethod(Invoker.java:580)
at org.testng.internal.Invoker.invokeTestMethod(Invoker.java:716)
at org.testng.internal.Invoker.invokeTestMethods(Invoker.java:988)
at org.testng.internal.TestMethodWorker.invokeTestMethods(TestMethodWorker.java:125)
at org.testng.internal.TestMethodWorker.run(TestMethodWorker.java:109)
at org.testng.TestRunner.privateRun(TestRunner.java:648)
at org.testng.TestRunner.run(TestRunner.java:505)
at org.testng.SuiteRunner.runTest(SuiteRunner.java:455)
at org.testng.SuiteRunner.access$000(SuiteRunner.java:40)
at org.testng.SuiteRunner$SuiteWorker.run(SuiteRunner.java:489)
at org.testng.internal.thread.ThreadUtil$1.call(ThreadUtil.java:52)
at java.util.concurrent.FutureTask.run(Unknown Source)
at java.util.concurrent.ThreadPoolExecutor.runWorker(Unknown Source)
at java.util.concurrent.ThreadPoolExecutor$Worker.run(Unknown Source)
at java.lang.Thread.run(Unknown Source)
]]>
    </failure>
  </testcase> <!-- Test2 -->
  <testcase name="Test1" time="0.003" classname="com.qa.retryFailedTCUsingListener.TestCase">
    <skipped/>
  </testcase> <!-- Test1 -->
  <testcase name="Test1" time="0.004" classname="com.qa.retryFailedTCUsingListener.TestCase">
    <skipped/>
  </testcase> <!-- Test1 -->
  <testcase name="Test1" time="0.004" classname="com.qa.retryFailedTCUsingListener.TestCase">
    <skipped/>
  </testcase> <!-- Test1 -->
  <testcase name="Test1" time="0.002" classname="com.qa.retryFailedTCUsingListener.TestCase">
    <failure type="java.lang.AssertionError" message="expected [true] but found [false]">
      <![CDATA[java.lang.AssertionError: expected [true] but found [false]
at org.testng.Assert.fail(Assert.java:96)
at org.testng.Assert.failNotEquals(Assert.java:776)
at org.testng.Assert.assertEqualsImpl(Assert.java:137)
at org.testng.Assert.assertEquals(Assert.java:118)
at org.testng.Assert.assertEquals(Assert.java:568)
at org.testng.Assert.assertEquals(Assert.java:578)
at com.qa.retryFailedTCUsingListener.TestCase.Test1(TestCase.java:11)
at sun.reflect.NativeMethodAccessorImpl.invoke0(Native Method)
at sun.reflect.NativeMethodAccessorImpl.invoke(Unknown Source)
at sun.reflect.DelegatingMethodAccessorImpl.invoke(Unknown Source)
at java.lang.reflect.Method.invoke(Unknown Source)
at org.testng.internal.MethodInvocationHelper.invokeMethod(MethodInvocationHelper.java:124)
at org.testng.internal.Invoker.invokeMethod(Invoker.java:580)
at org.testng.internal.Invoker.retryFailed(Invoker.java:838)
at org.testng.internal.Invoker.invokeTestMethods(Invoker.java:1009)
at org.testng.internal.TestMethodWorker.invokeTestMethods(TestMethodWorker.java:125)
at org.testng.internal.TestMethodWorker.run(TestMethodWorker.java:109)
at org.testng.TestRunner.privateRun(TestRunner.java:648)
at org.testng.TestRunner.run(TestRunner.java:505)
at org.testng.SuiteRunner.runTest(SuiteRunner.java:455)
at org.testng.SuiteRunner.access$000(SuiteRunner.java:40)
at org.testng.SuiteRunner$SuiteWorker.run(SuiteRunner.java:489)
at org.testng.internal.thread.ThreadUtil$1.call(ThreadUtil.java:52)
at java.util.concurrent.FutureTask.run(Unknown Source)
at java.util.concurrent.ThreadPoolExecutor.runWorker(Unknown Source)
at java.util.concurrent.ThreadPoolExecutor$Worker.run(Unknown Source)
at java.lang.Thread.run(Unknown Source)
]]>
    </failure>
  </testcase> <!-- Test1 -->
</testsuite> <!-- com.qa.retryFailedTCUsingListener.TestCase -->
